<?xml version="1.0"?>
<robot name="skid_steer" xmlns:xacro="http://ros.org/wiki/xacro">

  <!-- Parameters -->
  <xacro:property name="wheel_radius" value="0.05"/>
  <xacro:property name="wheel_width" value="0.02"/>
  <xacro:property name="wheel_separation" value="0.3"/>

  <!-- Base link -->
  <link name="base_link">
    <visual>
      <geometry>
        <box size="0.4 0.3 0.1"/>
      </geometry>
      <material name="base_color">
        <color rgba="0.8 0.1 0.1 1.0"/>
      </material>
    </visual>
    <collision>
      <geometry>
        <box size="0.4 0.3 0.1"/>
      </geometry>
    </collision>
    <inertial>
      <mass value="10.0"/>
      <inertia ixx="0.1" ixy="0" ixz="0" iyy="0.1" iyz="0" izz="0.1"/>
    </inertial>
  </link>

  <!-- 4 wheels -->
  <xacro:macro name="wheel" params="name x y">
    <link name="${name}">
      <visual>
        <geometry>
          <cylinder radius="${wheel_radius}" length="${wheel_width}"/>
        </geometry>
        <material name="${name}_color">
          <color rgba="0.1 0.1 0.8 1.0"/>
        </material>
      </visual>
      <collision>
        <geometry>
          <cylinder radius="${wheel_radius}" length="${wheel_width}"/>
        </geometry>
      </collision>
      <inertial>
        <mass value="1.0"/>
        <inertia ixx="0.01" ixy="0" ixz="0" iyy="0.01" iyz="0" izz="0.01"/>
      </inertial>
    </link>
    <joint name="${name}_joint" type="continuous">
      <parent link="base_link"/>
      <child link="${name}"/>
      <origin xyz="${x} ${y} -${wheel_radius}" rpy="0 1.5708 0"/>
      <axis xyz="0 1 0"/>
    </joint>
  </xacro:macro>

  <!-- Wheel positions -->
  <xacro:wheel name="front_left_wheel"  x="0.15" y="0.15"/>
  <xacro:wheel name="front_right_wheel" x="0.15" y="-0.15"/>
  <xacro:wheel name="rear_left_wheel"   x="-0.15" y="0.15"/>
  <xacro:wheel name="rear_right_wheel"  x="-0.15" y="-0.15"/>

  <!-- Gazebo plugins for Gazebo Fortress -->
  <gazebo>
    <!-- ros2_control plugin -->
    <plugin name="ros2_control" filename="libgz_ros2_control.so">
      <parameters>$(find skid_steer_robot)/config/ros2_control.yaml</parameters>
    </plugin>
    
    <!-- Differential drive plugin for better wheel control -->
    <plugin name="diff_drive" filename="libgz_ros_diff_drive.so">
      <left_joint>front_left_wheel_joint</left_joint>
      <left_joint>rear_left_wheel_joint</left_joint>
      <right_joint>front_right_wheel_joint</right_joint>
      <right_joint>rear_right_wheel_joint</right_joint>
      <wheel_separation>0.3</wheel_separation>
      <wheel_diameter>0.1</wheel_diameter>
      <max_wheel_torque>20</max_wheel_torque>
      <max_wheel_acceleration>1.0</max_wheel_acceleration>
      <publish_odom>true</publish_odom>
      <publish_odom_tf>true</publish_odom_tf>
      <publish_wheel_tf>false</publish_wheel_tf>
      <odometry_frame>odom</odometry_frame>
      <robot_base_frame>base_link</robot_base_frame>
      <odometry_source>world</odometry_source>
      <ros>
        <remapping>cmd_vel:=cmd_vel</remapping>
        <remapping>odom:=odom</remapping>
      </ros>
    </plugin>
  </gazebo>

</robot>

